Traceback (most recent call last):
  File "/Users/macangelou/Documents/GitHub/TryHackMe/PythonForPentesters/venv/lib/python3.11/site-packages/urllib3/connection.py", line 203, in _new_conn
    sock = connection.create_connection(
           ^^^^^^^^^^^^^^^^^^^^^^^^^^^^^
  File "/Users/macangelou/Documents/GitHub/TryHackMe/PythonForPentesters/venv/lib/python3.11/site-packages/urllib3/util/connection.py", line 85, in create_connection
    raise err
  File "/Users/macangelou/Documents/GitHub/TryHackMe/PythonForPentesters/venv/lib/python3.11/site-packages/urllib3/util/connection.py", line 73, in create_connection
    sock.connect(sa)
TimeoutError: timed out

The above exception was the direct cause of the following exception:

Traceback (most recent call last):
  File "/Users/macangelou/Documents/GitHub/TryHackMe/PythonForPentesters/venv/lib/python3.11/site-packages/urllib3/connectionpool.py", line 790, in urlopen
    response = self._make_request(
               ^^^^^^^^^^^^^^^^^^^
  File "/Users/macangelou/Documents/GitHub/TryHackMe/PythonForPentesters/venv/lib/python3.11/site-packages/urllib3/connectionpool.py", line 496, in _make_request
    conn.request(
  File "/Users/macangelou/Documents/GitHub/TryHackMe/PythonForPentesters/venv/lib/python3.11/site-packages/urllib3/connection.py", line 395, in request
    self.endheaders()
  File "/Users/macangelou/anaconda3/lib/python3.11/http/client.py", line 1281, in endheaders
    self._send_output(message_body, encode_chunked=encode_chunked)
  File "/Users/macangelou/anaconda3/lib/python3.11/http/client.py", line 1041, in _send_output
    self.send(msg)
  File "/Users/macangelou/anaconda3/lib/python3.11/http/client.py", line 979, in send
    self.connect()
  File "/Users/macangelou/Documents/GitHub/TryHackMe/PythonForPentesters/venv/lib/python3.11/site-packages/urllib3/connection.py", line 243, in connect
    self.sock = self._new_conn()
                ^^^^^^^^^^^^^^^^
  File "/Users/macangelou/Documents/GitHub/TryHackMe/PythonForPentesters/venv/lib/python3.11/site-packages/urllib3/connection.py", line 212, in _new_conn
    raise ConnectTimeoutError(
urllib3.exceptions.ConnectTimeoutError: (<urllib3.connection.HTTPConnection object at 0x1023df3d0>, 'Connection to 10.10.93.79 timed out. (connect timeout=10)')

The above exception was the direct cause of the following exception:

Traceback (most recent call last):
  File "/Users/macangelou/Documents/GitHub/TryHackMe/PythonForPentesters/venv/lib/python3.11/site-packages/requests/adapters.py", line 486, in send
    resp = conn.urlopen(
           ^^^^^^^^^^^^^
  File "/Users/macangelou/Documents/GitHub/TryHackMe/PythonForPentesters/venv/lib/python3.11/site-packages/urllib3/connectionpool.py", line 844, in urlopen
    retries = retries.increment(
              ^^^^^^^^^^^^^^^^^^
  File "/Users/macangelou/Documents/GitHub/TryHackMe/PythonForPentesters/venv/lib/python3.11/site-packages/urllib3/util/retry.py", line 515, in increment
    raise MaxRetryError(_pool, url, reason) from reason  # type: ignore[arg-type]
    ^^^^^^^^^^^^^^^^^^^^^^^^^^^^^^^^^^^^^^^^^^^^^^^^^^^
urllib3.exceptions.MaxRetryError: HTTPConnectionPool(host='10.10.93.79', port=80): Max retries exceeded with url: /123456.html (Caused by ConnectTimeoutError(<urllib3.connection.HTTPConnection object at 0x1023df3d0>, 'Connection to 10.10.93.79 timed out. (connect timeout=10)'))

During handling of the above exception, another exception occurred:

Traceback (most recent call last):
  File "/Users/macangelou/Documents/GitHub/TryHackMe/PythonForPentesters/direnum.py", line 13, in <module>
    r = requests.get(dir_enum, timeout=10)
        ^^^^^^^^^^^^^^^^^^^^^^^^^^^^^^^^^^
  File "/Users/macangelou/Documents/GitHub/TryHackMe/PythonForPentesters/venv/lib/python3.11/site-packages/requests/api.py", line 73, in get
    return request("get", url, params=params, **kwargs)
           ^^^^^^^^^^^^^^^^^^^^^^^^^^^^^^^^^^^^^^^^^^^^
  File "/Users/macangelou/Documents/GitHub/TryHackMe/PythonForPentesters/venv/lib/python3.11/site-packages/requests/api.py", line 59, in request
    return session.request(method=method, url=url, **kwargs)
           ^^^^^^^^^^^^^^^^^^^^^^^^^^^^^^^^^^^^^^^^^^^^^^^^^
  File "/Users/macangelou/Documents/GitHub/TryHackMe/PythonForPentesters/venv/lib/python3.11/site-packages/requests/sessions.py", line 589, in request
    resp = self.send(prep, **send_kwargs)
           ^^^^^^^^^^^^^^^^^^^^^^^^^^^^^^
  File "/Users/macangelou/Documents/GitHub/TryHackMe/PythonForPentesters/venv/lib/python3.11/site-packages/requests/sessions.py", line 703, in send
    r = adapter.send(request, **kwargs)
        ^^^^^^^^^^^^^^^^^^^^^^^^^^^^^^^
  File "/Users/macangelou/Documents/GitHub/TryHackMe/PythonForPentesters/venv/lib/python3.11/site-packages/requests/adapters.py", line 507, in send
    raise ConnectTimeout(e, request=request)
requests.exceptions.ConnectTimeout: HTTPConnectionPool(host='10.10.93.79', port=80): Max retries exceeded with url: /123456.html (Caused by ConnectTimeoutError(<urllib3.connection.HTTPConnection object at 0x1023df3d0>, 'Connection to 10.10.93.79 timed out. (connect timeout=10)'))
